<?xml version="1.0" ?>
<!-- Generated using onshape-to-robot -->
<!-- Onshape https://cad.onshape.com/documents/08933ab28552466369dd45f5/v/1c89bc95f2db2850ca32f781/e/79536a7a5ce948f49fbe9218 -->
<mujoco model="testbench">
  <compiler angle="radian" meshdir="assets" autolimits="true"/>
  <default>
    <default class="testbench">
      <joint frictionloss="0.1" armature="0.005"/>
      <position kp="50" dampratio="1"/>
      <default class="visual">
        <geom type="mesh" contype="0" conaffinity="0" group="2"/>
      </default>
      <default class="collision">
        <geom group="3"/>
      </default>
    </default>
  </default>
  <!-- Additional imu_sensor.xml -->
  <sensor>
    <accelerometer name="imu_acc" site="imu_site" noise="0.01"/>
    <gyro name="imu_gyro" site="imu_site" noise="0.01"/>
    <magnetometer name="imu_mag" site="imu_site" noise="0.05"/>
    <framepos name="base_link_pos" objtype="site" objname="imu_site"/>
    <framequat name="base_link_quat" objtype="site" objname="imu_site"/>
    <framelinvel name="base_link_vel" objtype="site" objname="imu_site"/>
    <frameangvel name="base_link_ang_vel" objtype="site" objname="imu_site"/>
  </sensor>
  <worldbody>
    <!-- Link motor_mount -->
    <body name="motor_mount" pos="0 0 0.3" quat="1 0 0 0" childclass="testbench">
      <!-- <freejoint name="motor_mount_freejoint"/> -->
      <inertial pos="0.011359 0.0790473 0.213984" mass="0.341126" fullinertia="0.000799198 0.00027571 0.000907808 -5.09171e-08 -5.66817e-08 -0.00012762"/>
      <!-- Part motor_mount -->
      <geom type="mesh" class="visual" pos="0.0113618 0.0117253 0.176057" quat="1 0 0 0" mesh="motor_mount" material="motor_mount_material"/>
      <!-- Part sts3215 -->
      <geom type="mesh" class="visual" pos="0.0113618 0.0304755 0.176057" quat="0.5 0.5 -0.5 0.5" mesh="sts3215" material="sts3215_material"/>
      <!-- Link motor_weight_mount -->
      <body name="motor_weight_mount" pos="0.0113618 0.0121756 0.176057" quat="0.707107 -0.707107 0 4.32978e-17">
        <!-- Joint from motor_mount to motor_weight_mount -->
        <joint axis="0 0 1" name="servo_out" type="hinge" range="-1.5707963267948966 1.5707963267948966"/>
        <inertial pos="5.0223e-10 0.0841529 0.0130883" mass="0.161583" fullinertia="0.000374781 5.97011e-05 0.000334123 2.11771e-12 8.70757e-13 4.1884e-05"/>
        <!-- Part imu -->
        <geom type="mesh" class="visual" pos="0 0.13 -0.012675" quat="1.28347e-16 -0.707107 -0.707107 -4.17513e-17" mesh="imu" material="imu_material"/>
        <!-- Part motor_weight_mount -->
        <geom type="mesh" class="visual" pos="0 0 -1.76346e-18" quat="0.707107 0.707107 -0 -3.84093e-49" mesh="motor_weight_mount" material="motor_weight_mount_material"/>
        <!-- Part weight_plug -->
        <geom type="mesh" class="visual" pos="0 0 0.0005" quat="0.707107 0.707107 -0 -3.84093e-49" mesh="weight_plug" material="weight_plug_material"/>
        <!-- Frame imu_site -->
        <site group="3" name="imu_site" pos="0 0.13 -0.012425" quat="8.5899e-17 -0.707107 -0.707107 -8.5899e-17"/>
      </body>
    </body>
  </worldbody>
  <asset>
    <mesh file="weight_plug.stl"/>
    <mesh file="imu.stl"/>
    <mesh file="motor_mount.stl"/>
    <mesh file="motor_weight_mount.stl"/>
    <mesh file="sts3215.stl"/>
    <material name="motor_mount_material" rgba="0.541176 0.682353 0.839216 1"/>
    <material name="sts3215_material" rgba="1 0 0 1"/>
    <material name="imu_material" rgba="0.615686 0.811765 0.929412 1"/>
    <material name="motor_weight_mount_material" rgba="0.972549 0.529412 0.00392157 1"/>
    <material name="weight_plug_material" rgba="0.498039 0.498039 0.498039 1"/>
  </asset>
  <actuator>
    <position class="testbench" name="servo_out" joint="servo_out" inheritrange="1"/>
  </actuator>
  <equality/>
</mujoco>
